Workbook
Name IQ_CH: 110000
Name IQ_CQ: 5000
Name IQ_CY: 10000
Name IQ_DAILY: 500000
Name IQ_FH: 100000
Name IQ_FQ: 500
Name IQ_FY: 1000
Name IQ_LTM: 2000
Name IQ_MONTH: 15000
Name IQ_NTM: 6000
Name IQ_WEEK: 50000
Name IQ_YTD: 3000
Name UPDATE: 'Data Sheet 1'!$E$1

Sheet Financials>

Sheet HistoricalFS
B2: ="Historical Financial Statement - "&'Data Sheet 1'!B1
B3: Years | C3: ='Data Sheet 1'!B16 | D3: ='Data Sheet 1'!C16 | E3: ='Data Sheet 1'!D16 | F3: ='Data Sheet 1'!E16 | G3: ='Data Sheet 1'!F16 | H3: ='Data Sheet 1'!G16 | I3: ='Data Sheet 1'!H16 | J3: ='Data Sheet 1'!I16 | ... L3: ='Data Sheet 1'!K16 | M3: LTM
A5: # | B5: Income Statement
B6: Sales | C6: =IFERROR('Data Sheet 1'!B17,0) | D6: =IFERROR('Data Sheet 1'!C17,0) | E6: =IFERROR('Data Sheet 1'!D17,0) | F6: =IFERROR('Data Sheet 1'!E17,0) | G6: =IFERROR('Data Sheet 1'!F17,0) | H6: =IFERROR('Data Sheet 1'!G17,0) | I6: =IFERROR('Data Sheet 1'!H17,0) | J6: =IFERROR('Data Sheet 1'!I17,0) | ... L6: =IFERROR('Data Sheet 1'!K17,0) | M6: =IFERROR(SUM('Data Sheet 1'!H36:K36),0)
B7: Sales Growth | C7: - | D7: =D6/C6-1 | E7: =E6/D6-1 | F7: =F6/E6-1 | G7: =G6/F6-1 | H7: =H6/G6-1 | I7: =I6/H6-1 | J7: =J6/I6-1 | K7: =K6/J6-1 | ... M7: =M6/L6-1
B9: COGS | C9: =IFERROR(SUM('Data Sheet 1'!B18,'Data Sheet 1'!B20:B22)-1*'Data Sheet 1'!B19,0) | D9: =IFERROR(SUM('Data Sheet 1'!C18,'Data Sheet 1'!C20:C22)-1*'Data Sheet 1'!C19,0) | E9: =IFERROR(SUM('Data Sheet 1'!D18,'Data Sheet 1'!D20:D22)-1*'Data Sheet 1'!D19,0) | F9: =IFERROR(SUM('Data Sheet 1'!E18,'Data Sheet 1'!E20:E22)-1*'Data Sheet 1'!E19,0) | G9: =IFERROR(SUM('Data Sheet 1'!F18,'Data Sheet 1'!F20:F22)-1*'Data Sheet 1'!F19,0) | H9: =IFERROR(SUM('Data Sheet 1'!G18,'Data Sheet 1'!G20:G22)-1*'Data Sheet 1'!G19,0) | I9: =IFERROR(SUM('Data Sheet 1'!H18,'Data Sheet 1'!H20:H22)-1*'Data Sheet 1'!H19,0) | J9: =IFERROR(SUM('Data Sheet 1'!I18,'Data Sheet 1'!I20:I22)-1*'Data Sheet 1'!I19,0) | ... L9: =IFERROR(SUM('Data Sheet 1'!K18,'Data Sheet 1'!K20:K22)-1*'Data Sheet 1'!K19,0) | M9: =IFERROR(SUM('Data Sheet 1'!H37:K37,),0)
B10: COGS % Sales | C10: =C9/C6 | D10: =D9/D6 | E10: =E9/E6 | F10: =F9/F6 | G10: =G9/G6 | H10: =H9/H6 | I10: =I9/I6 | J10: =J9/J6 | ... M10: =M9/M6
B12: Gross Profit | C12: =C6-C9 | D12: =D6-D9 | E12: =E6-E9 | F12: =F6-F9 | G12: =G6-G9 | H12: =H6-H9 | I12: =I6-I9 | J12: =J6-J9 | ... M12: =M6-M9
B13: Gross Margins | C13: =C12/C6 | D13: =D12/D6 | E13: =E12/E6 | F13: =F12/F6 | G13: =G12/G6 | H13: =H12/H6 | I13: =I12/I6 | J13: =J12/J6 | ... M13: =M12/M6
B15: Selling & General Expenses | C15: =IFERROR(SUM('Data Sheet 1'!B23:B24),0) | D15: =IFERROR(SUM('Data Sheet 1'!C23:C24),0) | E15: =IFERROR(SUM('Data Sheet 1'!D23:D24),0) | F15: =IFERROR(SUM('Data Sheet 1'!E23:E24),0) | G15: =IFERROR(SUM('Data Sheet 1'!F23:F24),0) | H15: =IFERROR(SUM('Data Sheet 1'!G23:G24),0) | I15: =IFERROR(SUM('Data Sheet 1'!H23:H24),0) | J15: =IFERROR(SUM('Data Sheet 1'!I23:I24),0) | ... M15: =IFERROR(SUM('Data Sheet 1'!L23:L24),0)
B16: S&G Exp % Sales | C16: =C15/C6 | D16: =D15/D6 | E16: =E15/E6 | F16: =F15/F6 | G16: =G15/G6 | H16: =H15/H6 | I16: =I15/I6 | J16: =J15/J6 | ... M16: =M15/M6
B18: EBITDA | C18: =C12-C15 | D18: =D12-D15 | E18: =E12-E15 | F18: =F12-F15 | G18: =G12-G15 | H18: =H12-H15 | I18: =I12-I15 | J18: =J12-J15 | ... M18: =M12-M15
B19: EBITDA Margins | C19: =C18/C6 | D19: =D18/D6 | E19: =E18/E6 | F19: =F18/F6 | G19: =G18/G6 | H19: =H18/H6 | I19: =I18/I6 | J19: =J18/J6 | ... L19: =L18/L6
B21: Interest | C21: =IFERROR('Data Sheet 1'!B27,0) | D21: =IFERROR('Data Sheet 1'!C27,0) | E21: =IFERROR('Data Sheet 1'!D27,0) | F21: =IFERROR('Data Sheet 1'!E27,0) | G21: =IFERROR('Data Sheet 1'!F27,0) | H21: =IFERROR('Data Sheet 1'!G27,0) | I21: =IFERROR('Data Sheet 1'!H27,0) | J21: =IFERROR('Data Sheet 1'!I27,0) | ... L21: =IFERROR('Data Sheet 1'!K27,0) | M21: =IFERROR(SUM('Data Sheet 1'!H40:K40),0)
B22: Interest % Sales | C22: =C21/C6 | D22: =D21/D6 | E22: =E21/E6 | F22: =F21/F6 | G22: =G21/G6 | H22: =H21/H6 | I22: =I21/I6 | J22: =J21/J6 | ... M22: =M21/M6
B24: Depriciation | C24: =IFERROR('Data Sheet 1'!B26,0) | D24: =IFERROR('Data Sheet 1'!C26,0) | E24: =IFERROR('Data Sheet 1'!D26,0) | F24: =IFERROR('Data Sheet 1'!E26,0) | G24: =IFERROR('Data Sheet 1'!F26,0) | H24: =IFERROR('Data Sheet 1'!G26,0) | I24: =IFERROR('Data Sheet 1'!H26,0) | J24: =IFERROR('Data Sheet 1'!I26,0) | ... L24: =IFERROR('Data Sheet 1'!K26,0) | M24: =IFERROR(SUM('Data Sheet 1'!H39:K39),0)
B25: Depriciation % Sales | C25: =C24/C6 | D25: =D24/D6 | E25: =E24/E6 | F25: =F24/F6 | G25: =G24/G6 | H25: =H24/H6 | I25: =I24/I6 | J25: =J24/J6 | ... M25: =M24/M6
B27: Earning Before Tax + Other inc | C27: =IFERROR(C18-SUM(C21+C24)+'Data Sheet 1'!B25,0) | D27: =IFERROR(D18-SUM(D21+D24)+'Data Sheet 1'!C25,0) | E27: =IFERROR(E18-SUM(E21+E24)+'Data Sheet 1'!D25,0) | F27: =IFERROR(F18-SUM(F21+F24)+'Data Sheet 1'!E25,0) | G27: =IFERROR(G18-SUM(G21+G24)+'Data Sheet 1'!F25,0) | H27: =IFERROR(H18-SUM(H21+H24)+'Data Sheet 1'!G25,0) | I27: =IFERROR(I18-SUM(I21+I24)+'Data Sheet 1'!H25,0) | J27: =IFERROR(J18-SUM(J21+J24)+'Data Sheet 1'!I25,0) | ... L27: =IFERROR(L18-SUM(L21+L24)+'Data Sheet 1'!K25,0) | M27: =IFERROR(M18-SUM(M21+M24),0)
B28: EBT % Sales | C28: =C27/C6 | D28: =D27/D6 | E28: =E27/E6 | F28: =F27/F6 | G28: =G27/G6 | H28: =H27/H6 | I28: =I27/I6 | J28: =J27/J6 | ... M28: =M27/M6
B30: Tax | C30: =IFERROR('Data Sheet 1'!B29,0) | D30: =IFERROR('Data Sheet 1'!C29,0) | E30: =IFERROR('Data Sheet 1'!D29,0) | F30: =IFERROR('Data Sheet 1'!E29,0) | G30: =IFERROR('Data Sheet 1'!F29,0) | H30: =IFERROR('Data Sheet 1'!G29,0) | I30: =IFERROR('Data Sheet 1'!H29,0) | J30: =IFERROR('Data Sheet 1'!I29,0) | ... M30: =IFERROR('Data Sheet 1'!L29,0)
B31: Effective Tax Rate | C31: =C30/C27 | D31: =D30/D27 | E31: =E30/E27 | F31: =F30/F27 | G31: =G30/G27 | H31: =H30/H27 | I31: =I30/I27 | J31: =J30/J27 | ... M31: =M30/M27
B33: Net Profit | C33: =C27-C30 | D33: =D27-D30 | E33: =E27-E30 | F33: =F27-F30 | G33: =G27-G30 | H33: =H27-H30 | I33: =I27-I30 | J33: =J27-J30 | ... M33: =M27-M30
B34: Net Margins | C34: =C33/C6 | D34: =D33/D6 | E34: =E33/E6 | F34: =F33/F6 | G34: =G33/G6 | H34: =H33/H6 | I34: =I33/I6 | J34: =J33/J6 | ... M34: =M33/M6
B36: Number of Equity Shares | C36: =IFERROR('Data Sheet 1'!B77,0) | D36: =IFERROR('Data Sheet 1'!C77,0) | E36: =IFERROR('Data Sheet 1'!D77,0) | F36: =IFERROR('Data Sheet 1'!E77,0) | G36: =IFERROR('Data Sheet 1'!F77,0) | H36: =IFERROR('Data Sheet 1'!G77,0) | I36: =IFERROR('Data Sheet 1'!H77,0) | J36: =IFERROR('Data Sheet 1'!I77,0) | ... M36: =IFERROR('Data Sheet 1'!L77,0)
B38: Earning Per Share | C38: =IFERROR(C33/C36,0) | D38: =IFERROR(D33/D36,0) | E38: =IFERROR(E33/E36,0) | F38: =IFERROR(F33/F36,0) | G38: =IFERROR(G33/G36,0) | H38: =IFERROR(H33/H36,0) | I38: =IFERROR(I33/I36,0) | J38: =IFERROR(J33/J36,0) | ... M38: =IFERROR(M33/M36,0)
B39: EPS Growth % | D39: =IFERROR(D38/C38-1,0) | E39: =IFERROR(E38/D38-1,0) | F39: =IFERROR(F38/E38-1,0) | G39: =IFERROR(G38/F38-1,0) | H39: =IFERROR(H38/G38-1,0) | I39: =IFERROR(I38/H38-1,0) | J39: =IFERROR(J38/I38-1,0) | K39: =IFERROR(K38/J38-1,0) | ... M39: =IFERROR(M38/L38-1,0)
B41: Dividend per Share | C41: =IFERROR('Data Sheet 1'!B31/HistoricalFS!C36,0) | D41: =IFERROR('Data Sheet 1'!C31/HistoricalFS!D36,0) | E41: =IFERROR('Data Sheet 1'!D31/HistoricalFS!E36,0) | F41: =IFERROR('Data Sheet 1'!E31/HistoricalFS!F36,0) | G41: =IFERROR('Data Sheet 1'!F31/HistoricalFS!G36,0) | H41: =IFERROR('Data Sheet 1'!G31/HistoricalFS!H36,0) | I41: =IFERROR('Data Sheet 1'!H31/HistoricalFS!I36,0) | J41: =IFERROR('Data Sheet 1'!I31/HistoricalFS!J36,0) | ... M41: =IFERROR('Data Sheet 1'!L31/HistoricalFS!M36,0)
B42: Dividend payout ratio | C42: =IFERROR(C41/C38,0) | D42: =IFERROR(D41/D38,0) | E42: =IFERROR(E41/E38,0) | F42: =IFERROR(F41/F38,0) | G42: =IFERROR(G41/G38,0) | H42: =IFERROR(H41/H38,0) | I42: =IFERROR(I41/I38,0) | J42: =IFERROR(J41/J38,0) | ... M42: =IFERROR(M41/M38,0)
B44: Reatined Earnings | C44: =IFERROR(IF(C38>C41,1-C42,0),0) | D44: =IFERROR(IF(D38>D41,1-D42,0),0) | E44: =IFERROR(IF(E38>E41,1-E42,0),0) | F44: =IFERROR(IF(F38>F41,1-F42,0),0) | G44: =IFERROR(IF(G38>G41,1-G42,0),0) | H44: =IFERROR(IF(H38>H41,1-H42,0),0) | I44: =IFERROR(IF(I38>I41,1-I42,0),0) | J44: =IFERROR(IF(J38>J41,1-J42,0),0) | ... M44: =IFERROR(IF(M38>M41,1-M42,0),0)
A46: # | B46: Balance Sheet
B47: Equity Share Capital | C47: =IFERROR('Data Sheet 1'!B49,0) | D47: =IFERROR('Data Sheet 1'!C49,0) | E47: =IFERROR('Data Sheet 1'!D49,0) | F47: =IFERROR('Data Sheet 1'!E49,0) | G47: =IFERROR('Data Sheet 1'!F49,0) | H47: =IFERROR('Data Sheet 1'!G49,0) | I47: =IFERROR('Data Sheet 1'!H49,0) | J47: =IFERROR('Data Sheet 1'!I49,0) | ... M47: =IFERROR('Data Sheet 1'!L49,0)
B48: Reserves | C48: =IFERROR('Data Sheet 1'!B50,0) | D48: =IFERROR('Data Sheet 1'!C50,0) | E48: =IFERROR('Data Sheet 1'!D50,0) | F48: =IFERROR('Data Sheet 1'!E50,0) | G48: =IFERROR('Data Sheet 1'!F50,0) | H48: =IFERROR('Data Sheet 1'!G50,0) | I48: =IFERROR('Data Sheet 1'!H50,0) | J48: =IFERROR('Data Sheet 1'!I50,0) | ... M48: =IFERROR('Data Sheet 1'!L50,0)
B49: Borrowings | C49: =IFERROR('Data Sheet 1'!B51,0) | D49: =IFERROR('Data Sheet 1'!C51,0) | E49: =IFERROR('Data Sheet 1'!D51,0) | F49: =IFERROR('Data Sheet 1'!E51,0) | G49: =IFERROR('Data Sheet 1'!F51,0) | H49: =IFERROR('Data Sheet 1'!G51,0) | I49: =IFERROR('Data Sheet 1'!H51,0) | J49: =IFERROR('Data Sheet 1'!I51,0) | ... M49: =IFERROR('Data Sheet 1'!L51,0)
B50: Other Liabilities | C50: =IFERROR('Data Sheet 1'!B52,0) | D50: =IFERROR('Data Sheet 1'!C52,0) | E50: =IFERROR('Data Sheet 1'!D52,0) | F50: =IFERROR('Data Sheet 1'!E52,0) | G50: =IFERROR('Data Sheet 1'!F52,0) | H50: =IFERROR('Data Sheet 1'!G52,0) | I50: =IFERROR('Data Sheet 1'!H52,0) | J50: =IFERROR('Data Sheet 1'!I52,0) | ... M50: =IFERROR('Data Sheet 1'!L52,0)
B51: Total Liabilities | C51: =IFERROR('Data Sheet 1'!B53,0) | D51: =IFERROR('Data Sheet 1'!C53,0) | E51: =IFERROR('Data Sheet 1'!D53,0) | F51: =IFERROR('Data Sheet 1'!E53,0) | G51: =IFERROR('Data Sheet 1'!F53,0) | H51: =IFERROR('Data Sheet 1'!G53,0) | I51: =IFERROR('Data Sheet 1'!H53,0) | J51: =IFERROR('Data Sheet 1'!I53,0) | ... M51: =IFERROR('Data Sheet 1'!L53,0)
B53: Fixed Assets Net Block | C53: =IFERROR('Data Sheet 1'!B54,0) | D53: =IFERROR('Data Sheet 1'!C54,0) | E53: =IFERROR('Data Sheet 1'!D54,0) | F53: =IFERROR('Data Sheet 1'!E54,0) | G53: =IFERROR('Data Sheet 1'!F54,0) | H53: =IFERROR('Data Sheet 1'!G54,0) | I53: =IFERROR('Data Sheet 1'!H54,0) | J53: =IFERROR('Data Sheet 1'!I54,0) | ... M53: =IFERROR('Data Sheet 1'!L54,0)
B54: Capital Work in Progress | C54: =IFERROR('Data Sheet 1'!B55,0) | D54: =IFERROR('Data Sheet 1'!C55,0) | E54: =IFERROR('Data Sheet 1'!D55,0) | F54: =IFERROR('Data Sheet 1'!E55,0) | G54: =IFERROR('Data Sheet 1'!F55,0) | H54: =IFERROR('Data Sheet 1'!G55,0) | I54: =IFERROR('Data Sheet 1'!H55,0) | J54: =IFERROR('Data Sheet 1'!I55,0) | ... M54: =IFERROR('Data Sheet 1'!L55,0)
B55: Investments | C55: =IFERROR('Data Sheet 1'!B56,0) | D55: =IFERROR('Data Sheet 1'!C56,0) | E55: =IFERROR('Data Sheet 1'!D56,0) | F55: =IFERROR('Data Sheet 1'!E56,0) | G55: =IFERROR('Data Sheet 1'!F56,0) | H55: =IFERROR('Data Sheet 1'!G56,0) | I55: =IFERROR('Data Sheet 1'!H56,0) | J55: =IFERROR('Data Sheet 1'!I56,0) | ... M55: =IFERROR('Data Sheet 1'!L56,0)
B56: Other Assets | C56: =IFERROR('Data Sheet 1'!B57-SUM('Data Sheet 1'!B59:B61),0) | D56: =IFERROR('Data Sheet 1'!C57-SUM('Data Sheet 1'!C59:C61),0) | E56: =IFERROR('Data Sheet 1'!D57-SUM('Data Sheet 1'!D59:D61),0) | F56: =IFERROR('Data Sheet 1'!E57-SUM('Data Sheet 1'!E59:E61),0) | G56: =IFERROR('Data Sheet 1'!F57-SUM('Data Sheet 1'!F59:F61),0) | H56: =IFERROR('Data Sheet 1'!G57-SUM('Data Sheet 1'!G59:G61),0) | I56: =IFERROR('Data Sheet 1'!H57-SUM('Data Sheet 1'!H59:H61),0) | J56: =IFERROR('Data Sheet 1'!I57-SUM('Data Sheet 1'!I59:I61),0) | ... M56: =IFERROR('Data Sheet 1'!L57-SUM('Data Sheet 1'!L59:L61),0)
B57: Total Non Current Assets | C57: =IFERROR(SUM(C53:C56),0) | D57: =IFERROR(SUM(D53:D56),0) | E57: =IFERROR(SUM(E53:E56),0) | F57: =IFERROR(SUM(F53:F56),0) | G57: =IFERROR(SUM(G53:G56),0) | H57: =IFERROR(SUM(H53:H56),0) | I57: =IFERROR(SUM(I53:I56),0) | J57: =IFERROR(SUM(J53:J56),0) | ... M57: =IFERROR(SUM(M53:M56),0)
...

Sheet Ratio Analysis
B2: ="Historical Financial Statement - "&'Data Sheet 1'!B1
B3: Years | C3: ='Data Sheet 1'!B16 | D3: ='Data Sheet 1'!C16 | E3: ='Data Sheet 1'!D16 | F3: ='Data Sheet 1'!E16 | G3: ='Data Sheet 1'!F16 | H3: ='Data Sheet 1'!G16 | I3: ='Data Sheet 1'!H16 | J3: ='Data Sheet 1'!I16 | ... L3: ='Data Sheet 1'!K16 | M3: Trend | N3: Mean | O3: Median
B5: Sales Growth | D5: =IFERROR(HistoricalFS!D7,0) | E5: =IFERROR(HistoricalFS!E7,0) | F5: =IFERROR(HistoricalFS!F7,0) | G5: =IFERROR(HistoricalFS!G7,0) | H5: =IFERROR(HistoricalFS!H7,0) | I5: =IFERROR(HistoricalFS!I7,0) | J5: =IFERROR(HistoricalFS!J7,0) | K5: =IFERROR(HistoricalFS!K7,0) | L5: =IFERROR(HistoricalFS!L7,0) | N5: =IFERROR(AVERAGE(D5:L5),0) | O5: =IFERROR(MEDIAN(C5:L5),0)
B6: EBITDA Growth | D6: =IFERROR(HistoricalFS!D18/HistoricalFS!C18-1,0) | E6: =IFERROR(HistoricalFS!E18/HistoricalFS!D18-1,0) | F6: =IFERROR(HistoricalFS!F18/HistoricalFS!E18-1,0) | G6: =IFERROR(HistoricalFS!G18/HistoricalFS!F18-1,0) | H6: =IFERROR(HistoricalFS!H18/HistoricalFS!G18-1,0) | I6: =IFERROR(HistoricalFS!I18/HistoricalFS!H18-1,0) | J6: =IFERROR(HistoricalFS!J18/HistoricalFS!I18-1,0) | K6: =IFERROR(HistoricalFS!K18/HistoricalFS!J18-1,0) | L6: =IFERROR(HistoricalFS!L18/HistoricalFS!K18-1,0) | N6: =IFERROR(AVERAGE(D6:L6),0) | O6: =IFERROR(MEDIAN(C6:L6),0)
B7: EBIT Growth | D7: =IFERROR(HistoricalFS!D27/HistoricalFS!C27-1,0) | E7: =IFERROR(HistoricalFS!E27/HistoricalFS!D27-1,0) | F7: =IFERROR(HistoricalFS!F27/HistoricalFS!E27-1,0) | G7: =IFERROR(HistoricalFS!G27/HistoricalFS!F27-1,0) | H7: =IFERROR(HistoricalFS!H27/HistoricalFS!G27-1,0) | I7: =IFERROR(HistoricalFS!I27/HistoricalFS!H27-1,0) | J7: =IFERROR(HistoricalFS!J27/HistoricalFS!I27-1,0) | K7: =IFERROR(HistoricalFS!K27/HistoricalFS!J27-1,0) | L7: =IFERROR(HistoricalFS!L27/HistoricalFS!K27-1,0) | N7: =IFERROR(AVERAGE(D7:L7),0) | O7: =IFERROR(MEDIAN(C7:L7),0)
B8: Net Profit Growth | D8: =IFERROR(HistoricalFS!D33/HistoricalFS!C33-1,0) | E8: =IFERROR(HistoricalFS!E33/HistoricalFS!D33-1,0) | F8: =IFERROR(HistoricalFS!F33/HistoricalFS!E33-1,0) | G8: =IFERROR(HistoricalFS!G33/HistoricalFS!F33-1,0) | H8: =IFERROR(HistoricalFS!H33/HistoricalFS!G33-1,0) | I8: =IFERROR(HistoricalFS!I33/HistoricalFS!H33-1,0) | J8: =IFERROR(HistoricalFS!J33/HistoricalFS!I33-1,0) | K8: =IFERROR(HistoricalFS!K33/HistoricalFS!J33-1,0) | L8: =IFERROR(HistoricalFS!L33/HistoricalFS!K33-1,0) | N8: =IFERROR(AVERAGE(D8:L8),0) | O8: =IFERROR(MEDIAN(C8:L8),0)
B9: Dividend Growth | D9: =IFERROR(HistoricalFS!D41/HistoricalFS!C41-1,0) | E9: =IFERROR(HistoricalFS!E41/HistoricalFS!D41-1,0) | F9: =IFERROR(HistoricalFS!F41/HistoricalFS!E41-1,0) | G9: =IFERROR(HistoricalFS!G41/HistoricalFS!F41-1,0) | H9: =IFERROR(HistoricalFS!H41/HistoricalFS!G41-1,0) | I9: =IFERROR(HistoricalFS!I41/HistoricalFS!H41-1,0) | J9: =IFERROR(HistoricalFS!J41/HistoricalFS!I41-1,0) | K9: =IFERROR(HistoricalFS!K41/HistoricalFS!J41-1,0) | L9: =IFERROR(HistoricalFS!L41/HistoricalFS!K41-1,0) | N9: =IFERROR(AVERAGE(D9:L9),0) | O9: =IFERROR(MEDIAN(C9:L9),0)
B11: Gross Margin | C11: =IFERROR(HistoricalFS!C13,0) | D11: =IFERROR(HistoricalFS!D13,0) | E11: =IFERROR(HistoricalFS!E13,0) | F11: =IFERROR(HistoricalFS!F13,0) | G11: =IFERROR(HistoricalFS!G13,0) | H11: =IFERROR(HistoricalFS!H13,0) | I11: =IFERROR(HistoricalFS!I13,0) | J11: =IFERROR(HistoricalFS!J13,0) | ... L11: =IFERROR(HistoricalFS!L13,0) | N11: =IFERROR(AVERAGE(C11:L11),0) | O11: =IFERROR(MEDIAN(C11:L11),0)
B12: EBITDA Margin | C12: =IFERROR(HistoricalFS!C19,0) | D12: =IFERROR(HistoricalFS!D19,0) | E12: =IFERROR(HistoricalFS!E19,0) | F12: =IFERROR(HistoricalFS!F19,0) | G12: =IFERROR(HistoricalFS!G19,0) | H12: =IFERROR(HistoricalFS!H19,0) | I12: =IFERROR(HistoricalFS!I19,0) | J12: =IFERROR(HistoricalFS!J19,0) | ... L12: =IFERROR(HistoricalFS!L19,0) | N12: =IFERROR(AVERAGE(C12:L12),0) | O12: =IFERROR(MEDIAN(C12:L12),0)
B13: EBIT Margin | C13: =IFERROR((HistoricalFS!C18-HistoricalFS!C24)/HistoricalFS!C6,0) | D13: =IFERROR((HistoricalFS!D18-HistoricalFS!D24)/HistoricalFS!D6,0) | E13: =IFERROR((HistoricalFS!E18-HistoricalFS!E24)/HistoricalFS!E6,0) | F13: =IFERROR((HistoricalFS!F18-HistoricalFS!F24)/HistoricalFS!F6,0) | G13: =IFERROR((HistoricalFS!G18-HistoricalFS!G24)/HistoricalFS!G6,0) | H13: =IFERROR((HistoricalFS!H18-HistoricalFS!H24)/HistoricalFS!H6,0) | I13: =IFERROR((HistoricalFS!I18-HistoricalFS!I24)/HistoricalFS!I6,0) | J13: =IFERROR((HistoricalFS!J18-HistoricalFS!J24)/HistoricalFS!J6,0) | ... L13: =IFERROR((HistoricalFS!L18-HistoricalFS!L24)/HistoricalFS!L6,0) | N13: =IFERROR(AVERAGE(C13:L13),0) | O13: =IFERROR(MEDIAN(C13:L13),0)
B14: EBT Margin | C14: =IFERROR(HistoricalFS!C28,0) | D14: =IFERROR(HistoricalFS!D28,0) | E14: =IFERROR(HistoricalFS!E28,0) | F14: =IFERROR(HistoricalFS!F28,0) | G14: =IFERROR(HistoricalFS!G28,0) | H14: =IFERROR(HistoricalFS!H28,0) | I14: =IFERROR(HistoricalFS!I28,0) | J14: =IFERROR(HistoricalFS!J28,0) | ... L14: =IFERROR(HistoricalFS!L28,0) | N14: =IFERROR(AVERAGE(C14:L14),0) | O14: =IFERROR(MEDIAN(C14:L14),0)
B15: Net Profit Margin | C15: =IFERROR(HistoricalFS!C34,0) | D15: =IFERROR(HistoricalFS!D34,0) | E15: =IFERROR(HistoricalFS!E34,0) | F15: =IFERROR(HistoricalFS!F34,0) | G15: =IFERROR(HistoricalFS!G34,0) | H15: =IFERROR(HistoricalFS!H34,0) | I15: =IFERROR(HistoricalFS!I34,0) | J15: =IFERROR(HistoricalFS!J34,0) | ... L15: =IFERROR(HistoricalFS!L34,0) | N15: =IFERROR(AVERAGE(C15:L15),0) | O15: =IFERROR(MEDIAN(C15:L15),0)
B17: Sales Expenses % Sales | C17: =IFERROR(HistoricalFS!C16,0) | D17: =IFERROR(HistoricalFS!D16,0) | E17: =IFERROR(HistoricalFS!E16,0) | F17: =IFERROR(HistoricalFS!F16,0) | G17: =IFERROR(HistoricalFS!G16,0) | H17: =IFERROR(HistoricalFS!H16,0) | I17: =IFERROR(HistoricalFS!I16,0) | J17: =IFERROR(HistoricalFS!J16,0) | ... L17: =IFERROR(HistoricalFS!L16,0) | N17: =IFERROR(AVERAGE(C17:L17),0) | O17: =IFERROR(MEDIAN(C17:L17),0)
B18: Depricaiation % Sales | C18: =IFERROR(HistoricalFS!C25,0) | D18: =IFERROR(HistoricalFS!D25,0) | E18: =IFERROR(HistoricalFS!E25,0) | F18: =IFERROR(HistoricalFS!F25,0) | G18: =IFERROR(HistoricalFS!G25,0) | H18: =IFERROR(HistoricalFS!H25,0) | I18: =IFERROR(HistoricalFS!I25,0) | J18: =IFERROR(HistoricalFS!J25,0) | ... L18: =IFERROR(HistoricalFS!L25,0) | N18: =IFERROR(AVERAGE(C18:L18),0) | O18: =IFERROR(MEDIAN(C18:L18),0)
B19: Operating Income % Sales | C19: =C13 | D19: =D13 | E19: =E13 | F19: =F13 | G19: =G13 | H19: =H13 | I19: =I13 | J19: =J13 | ... L19: =L13 | N19: =IFERROR(AVERAGE(C19:L19),0) | O19: =IFERROR(MEDIAN(C19:L19),0)
B21: Return on Capital Employed | C21: =IFERROR((HistoricalFS!C18-HistoricalFS!C24)/(SUM(HistoricalFS!C47:C49)),0) | D21: =IFERROR((HistoricalFS!D18-HistoricalFS!D24)/(SUM(HistoricalFS!D47:D49)),0) | E21: =IFERROR((HistoricalFS!E18-HistoricalFS!E24)/(SUM(HistoricalFS!E47:E49)),0) | F21: =IFERROR((HistoricalFS!F18-HistoricalFS!F24)/(SUM(HistoricalFS!F47:F49)),0) | G21: =IFERROR((HistoricalFS!G18-HistoricalFS!G24)/(SUM(HistoricalFS!G47:G49)),0) | H21: =IFERROR((HistoricalFS!H18-HistoricalFS!H24)/(SUM(HistoricalFS!H47:H49)),0) | I21: =IFERROR((HistoricalFS!I18-HistoricalFS!I24)/(SUM(HistoricalFS!I47:I49)),0) | J21: =IFERROR((HistoricalFS!J18-HistoricalFS!J24)/(SUM(HistoricalFS!J47:J49)),0) | ... L21: =IFERROR((HistoricalFS!L18-HistoricalFS!L24)/(SUM(HistoricalFS!L47:L49)),0) | N21: =IFERROR(AVERAGE(C21:L21),0) | O21: =IFERROR(MEDIAN(C21:L21),0)
B22: Retained Earning % | C22: =IFERROR(HistoricalFS!C44,0) | D22: =IFERROR(HistoricalFS!D44,0) | E22: =IFERROR(HistoricalFS!E44,0) | F22: =IFERROR(HistoricalFS!F44,0) | G22: =IFERROR(HistoricalFS!G44,0) | H22: =IFERROR(HistoricalFS!H44,0) | I22: =IFERROR(HistoricalFS!I44,0) | J22: =IFERROR(HistoricalFS!J44,0) | ... L22: =IFERROR(HistoricalFS!L44,0) | N22: =IFERROR(AVERAGE(C22:L22),0) | O22: =IFERROR(MEDIAN(C22:L22),0)
B23: Return on Equity % | C23: =IFERROR(HistoricalFS!C33/SUM(HistoricalFS!C47:C48),0) | D23: =IFERROR(HistoricalFS!D33/SUM(HistoricalFS!D47:D48),0) | E23: =IFERROR(HistoricalFS!E33/SUM(HistoricalFS!E47:E48),0) | F23: =IFERROR(HistoricalFS!F33/SUM(HistoricalFS!F47:F48),0) | G23: =IFERROR(HistoricalFS!G33/SUM(HistoricalFS!G47:G48),0) | H23: =IFERROR(HistoricalFS!H33/SUM(HistoricalFS!H47:H48),0) | I23: =IFERROR(HistoricalFS!I33/SUM(HistoricalFS!I47:I48),0) | J23: =IFERROR(HistoricalFS!J33/SUM(HistoricalFS!J47:J48),0) | ... L23: =IFERROR(HistoricalFS!L33/SUM(HistoricalFS!L47:L48),0) | N23: =IFERROR(AVERAGE(C23:L23),0) | O23: =IFERROR(MEDIAN(C23:L23),0)
B24: Self Sustained Growth Rate | C24: =IFERROR(C22*C23,0) | D24: =IFERROR(D22*D23,0) | E24: =IFERROR(E22*E23,0) | F24: =IFERROR(F22*F23,0) | G24: =IFERROR(G22*G23,0) | H24: =IFERROR(H22*H23,0) | I24: =IFERROR(I22*I23,0) | J24: =IFERROR(J22*J23,0) | ... L24: =IFERROR(L22*L23,0) | N24: =IFERROR(AVERAGE(C24:L24),0) | O24: =IFERROR(MEDIAN(C24:L24),0)
B25: Interest Coverage Ratio | C25: =(HistoricalFS!C18-HistoricalFS!C24)/HistoricalFS!C21 | D25: =(HistoricalFS!D18-HistoricalFS!D24)/HistoricalFS!D21 | E25: =(HistoricalFS!E18-HistoricalFS!E24)/HistoricalFS!E21 | F25: =(HistoricalFS!F18-HistoricalFS!F24)/HistoricalFS!F21 | G25: =(HistoricalFS!G18-HistoricalFS!G24)/HistoricalFS!G21 | H25: =(HistoricalFS!H18-HistoricalFS!H24)/HistoricalFS!H21 | I25: =(HistoricalFS!I18-HistoricalFS!I24)/HistoricalFS!I21 | J25: =(HistoricalFS!J18-HistoricalFS!J24)/HistoricalFS!J21 | ... L25: =(HistoricalFS!L18-HistoricalFS!L24)/HistoricalFS!L21 | N25: =IFERROR(AVERAGE(C25:L25),0) | O25: =IFERROR(MEDIAN(C25:L25),0)
B27: Debtor Turnover Ratio | C27: =IFERROR(HistoricalFS!C6/HistoricalFS!C59,0) | D27: =IFERROR(HistoricalFS!D6/HistoricalFS!D59,0) | E27: =IFERROR(HistoricalFS!E6/HistoricalFS!E59,0) | F27: =IFERROR(HistoricalFS!F6/HistoricalFS!F59,0) | G27: =IFERROR(HistoricalFS!G6/HistoricalFS!G59,0) | H27: =IFERROR(HistoricalFS!H6/HistoricalFS!H59,0) | I27: =IFERROR(HistoricalFS!I6/HistoricalFS!I59,0) | J27: =IFERROR(HistoricalFS!J6/HistoricalFS!J59,0) | ... L27: =IFERROR(HistoricalFS!L6/HistoricalFS!L59,0) | N27: =IFERROR(AVERAGE(C27:L27),0) | O27: =IFERROR(MEDIAN(C27:L27),0)
B28: Creditor Turnover Ratio | C28: =IFERROR(HistoricalFS!C6/HistoricalFS!C50,0) | D28: =IFERROR(HistoricalFS!D6/HistoricalFS!D50,0) | E28: =IFERROR(HistoricalFS!E6/HistoricalFS!E50,0) | F28: =IFERROR(HistoricalFS!F6/HistoricalFS!F50,0) | G28: =IFERROR(HistoricalFS!G6/HistoricalFS!G50,0) | H28: =IFERROR(HistoricalFS!H6/HistoricalFS!H50,0) | I28: =IFERROR(HistoricalFS!I6/HistoricalFS!I50,0) | J28: =IFERROR(HistoricalFS!J6/HistoricalFS!J50,0) | ... L28: =IFERROR(HistoricalFS!L6/HistoricalFS!L50,0) | N28: =IFERROR(AVERAGE(C28:L28),0) | O28: =IFERROR(MEDIAN(C28:L28),0)
B29: Inventory Turnover | C29: =IFERROR(HistoricalFS!C6/HistoricalFS!C60,0) | D29: =IFERROR(HistoricalFS!D6/HistoricalFS!D60,0) | E29: =IFERROR(HistoricalFS!E6/HistoricalFS!E60,0) | F29: =IFERROR(HistoricalFS!F6/HistoricalFS!F60,0) | G29: =IFERROR(HistoricalFS!G6/HistoricalFS!G60,0) | H29: =IFERROR(HistoricalFS!H6/HistoricalFS!H60,0) | I29: =IFERROR(HistoricalFS!I6/HistoricalFS!I60,0) | J29: =IFERROR(HistoricalFS!J6/HistoricalFS!J60,0) | ... L29: =IFERROR(HistoricalFS!L6/HistoricalFS!L60,0) | N29: =IFERROR(AVERAGE(C29:L29),0) | O29: =IFERROR(MEDIAN(C29:L29),0)
B30: Fixed Asset Turnover | C30: =IFERROR(HistoricalFS!C6/HistoricalFS!C5:C53,0) | D30: =IFERROR(HistoricalFS!D6/HistoricalFS!D5:D53,0) | E30: =IFERROR(HistoricalFS!E6/HistoricalFS!E5:E53,0) | F30: =IFERROR(HistoricalFS!F6/HistoricalFS!F5:F53,0) | G30: =IFERROR(HistoricalFS!G6/HistoricalFS!G5:G53,0) | H30: =IFERROR(HistoricalFS!H6/HistoricalFS!H5:H53,0) | I30: =IFERROR(HistoricalFS!I6/HistoricalFS!I5:I53,0) | J30: =IFERROR(HistoricalFS!J6/HistoricalFS!J5:J53,0) | ... L30: =IFERROR(HistoricalFS!L6/HistoricalFS!L5:L53,0) | N30: =IFERROR(AVERAGE(C30:L30),0) | O30: =IFERROR(MEDIAN(C30:L30),0)
B31: Capital Turnover | C31: =IFERROR(HistoricalFS!C6/SUM(HistoricalFS!C47:C48),0) | D31: =IFERROR(HistoricalFS!D6/SUM(HistoricalFS!D47:D48),0) | E31: =IFERROR(HistoricalFS!E6/SUM(HistoricalFS!E47:E48),0) | F31: =IFERROR(HistoricalFS!F6/SUM(HistoricalFS!F47:F48),0) | G31: =IFERROR(HistoricalFS!G6/SUM(HistoricalFS!G47:G48),0) | H31: =IFERROR(HistoricalFS!H6/SUM(HistoricalFS!H47:H48),0) | I31: =IFERROR(HistoricalFS!I6/SUM(HistoricalFS!I47:I48),0) | J31: =IFERROR(HistoricalFS!J6/SUM(HistoricalFS!J47:J48),0) | ... L31: =IFERROR(HistoricalFS!L6/SUM(HistoricalFS!L47:L48),0) | N31: =IFERROR(AVERAGE(C31:L31),0) | O31: =IFERROR(MEDIAN(C31:L31),0)
B33: (in days)
B34: Debtor Days | C34: =IFERROR(365/C27,0) | D34: =IFERROR(365/D27,0) | E34: =IFERROR(365/E27,0) | F34: =IFERROR(365/F27,0) | G34: =IFERROR(365/G27,0) | H34: =IFERROR(365/H27,0) | I34: =IFERROR(365/I27,0) | J34: =IFERROR(365/J27,0) | ... L34: =IFERROR(365/L27,0) | N34: =IFERROR(AVERAGE(C34:L34),0) | O34: =IFERROR(MEDIAN(C34:L34),0)
B35: Payable Days | C35: =IFERROR(365/C28,0) | D35: =IFERROR(365/D28,0) | E35: =IFERROR(365/E28,0) | F35: =IFERROR(365/F28,0) | G35: =IFERROR(365/G28,0) | H35: =IFERROR(365/H28,0) | I35: =IFERROR(365/I28,0) | J35: =IFERROR(365/J28,0) | ... L35: =IFERROR(365/L28,0) | N35: =IFERROR(AVERAGE(C35:L35),0) | O35: =IFERROR(MEDIAN(C35:L35),0)
B36: Inventory Days | C36: =IFERROR(365/C29,0) | D36: =IFERROR(365/D29,0) | E36: =IFERROR(365/E29,0) | F36: =IFERROR(365/F29,0) | G36: =IFERROR(365/G29,0) | H36: =IFERROR(365/H29,0) | I36: =IFERROR(365/I29,0) | J36: =IFERROR(365/J29,0) | ... L36: =IFERROR(365/L29,0) | N36: =IFERROR(AVERAGE(C36:L36),0) | O36: =IFERROR(MEDIAN(C36:L36),0)
B37: Cash Coversion Cycle | C37: =SUM(C34+C36)-C35 | D37: =SUM(D34+D36)-D35 | E37: =SUM(E34+E36)-E35 | F37: =SUM(F34+F36)-F35 | G37: =SUM(G34+G36)-G35 | H37: =SUM(H34+H36)-H35 | I37: =SUM(I34+I36)-I35 | J37: =SUM(J34+J36)-J35 | ... L37: =SUM(L34+L36)-L35 | N37: =IFERROR(AVERAGE(C37:L37),0) | O37: =IFERROR(MEDIAN(C37:L37),0)
B39: CFO/Sales | C39: =IFERROR(HistoricalFS!C78/HistoricalFS!C6,0) | D39: =IFERROR(HistoricalFS!D78/HistoricalFS!D6,0) | E39: =IFERROR(HistoricalFS!E78/HistoricalFS!E6,0) | F39: =IFERROR(HistoricalFS!F78/HistoricalFS!F6,0) | G39: =IFERROR(HistoricalFS!G78/HistoricalFS!G6,0) | H39: =IFERROR(HistoricalFS!H78/HistoricalFS!H6,0) | I39: =IFERROR(HistoricalFS!I78/HistoricalFS!I6,0) | J39: =IFERROR(HistoricalFS!J78/HistoricalFS!J6,0) | ... L39: =IFERROR(HistoricalFS!L78/HistoricalFS!L6,0) | N39: =IFERROR(AVERAGE(C39:L39),0) | O39: =IFERROR(MEDIAN(C39:L39),0)
B40: CFO/Total Assets | C40: =IFERROR(HistoricalFS!C78/HistoricalFS!C64,0) | D40: =IFERROR(HistoricalFS!D78/HistoricalFS!D64,0) | E40: =IFERROR(HistoricalFS!E78/HistoricalFS!E64,0) | F40: =IFERROR(HistoricalFS!F78/HistoricalFS!F64,0) | G40: =IFERROR(HistoricalFS!G78/HistoricalFS!G64,0) | H40: =IFERROR(HistoricalFS!H78/HistoricalFS!H64,0) | I40: =IFERROR(HistoricalFS!I78/HistoricalFS!I64,0) | J40: =IFERROR(HistoricalFS!J78/HistoricalFS!J64,0) | ... L40: =IFERROR(HistoricalFS!L78/HistoricalFS!L64,0) | N40: =IFERROR(AVERAGE(C40:L40),0) | O40: =IFERROR(MEDIAN(C40:L40),0)
B41: CFO/Total Debt | C41: =IFERROR(HistoricalFS!C78/HistoricalFS!C49,0) | D41: =IFERROR(HistoricalFS!D78/HistoricalFS!D49,0) | E41: =IFERROR(HistoricalFS!E78/HistoricalFS!E49,0) | F41: =IFERROR(HistoricalFS!F78/HistoricalFS!F49,0) | G41: =IFERROR(HistoricalFS!G78/HistoricalFS!G49,0) | H41: =IFERROR(HistoricalFS!H78/HistoricalFS!H49,0) | I41: =IFERROR(HistoricalFS!I78/HistoricalFS!I49,0) | J41: =IFERROR(HistoricalFS!J78/HistoricalFS!J49,0) | ... L41: =IFERROR(HistoricalFS!L78/HistoricalFS!L49,0) | N41: =IFERROR(AVERAGE(C41:L41),0) | O41: =IFERROR(MEDIAN(C41:L41),0)

Sheet Forcasting
B2: ='Data Sheet 1'!B1&" - "&'Data Sheet 1'!A17&" Forcasting"
B3: Year Weight | C3: Year | D3: Sales | E3: Sales Growth
B4: 1 | C4: ='Data Sheet 1'!B48 | D4: {=TRANSPOSE('Data Sheet 1'!B17:K17)}
B5: =B4+1 | C5: =C4+365 | D5: 16119.77 | E5: =D5/D4-1
B6: =B5+1 | C6: =C5+365 | D6: 19778.52 | E6: =D6/D5-1
B7: =B6+1 | C7: =C6+365 | D7: 21052 | E7: =D7/D6-1
B8: =B7+1 | C8: =C7+365 | D8: 21644 | E8: =D8/D7-1
B9: =B8+1 | C9: =C8+365 | D9: 28799 | E9: =D9/D8-1
B10: =B9+1 | C10: =C9+365 | D10: 40575 | E10: =D10/D9-1
B11: =B10+1 | C11: =C10+365 | D11: 51084 | E11: =D11/D10-1
B12: =B11+1 | C12: =C11+365 | D12: 60456 | E12: =D12/D11-1
B13: =B12+1 | C13: =C12+365 | D13: 87584 | E13: =D13/D12-1
B14: =B13+1 | C14: =C13+365 | D14: =FORECAST(B14,$D$4:$D$13,$B$4:$B$13) | E14: =D14/D13-1
B15: =B14+1 | C15: =C14+365 | D15: =FORECAST(B15,$D$4:$D$13,$B$4:$B$13) | E15: =D15/D14-1
B16: =B15+1 | C16: =C15+365 | D16: =FORECAST(B16,$D$4:$D$13,$B$4:$B$13) | E16: =D16/D15-1
B17: =B16+1 | C17: =C16+365 | D17: =FORECAST(B17,$D$4:$D$13,$B$4:$B$13) | E17: =D17/D16-1
B18: =B17+1 | C18: =C17+365 | D18: =FORECAST(B18,$D$4:$D$13,$B$4:$B$13) | E18: =D18/D17-1
B21: Do it for EBITDA & Earning per share

Sheet Data>

Sheet Data Sheet 1
A1: COMPANY NAME | B1: TITAN COMPANY LTD | E1: =IF(B2<>B3, "A NEW VERSION OF THE WORKSHEET IS AVAILABLE", "")
A2: LATEST VERSION | B2: 2.1 | E2: PLEASE DO NOT MAKE ANY CHANGES TO THIS SHEET
A3: CURRENT VERSION | B3: 2.1
A5: META
A6: Number of shares | B6: =IF(B9>0, B9/B8, 0)
A7: Face Value | B7: 1
A8: Current Price | B8: 4941
A9: Market Capitalization | B9: 438655.14
A15: PROFIT & LOSS
A16: Report Date | B16: 42825 | C16: 43190 | D16: 43555 | E16: 43921 | F16: 44286 | G16: 44651 | H16: 45016 | I16: 45382 | J16: 45747 | K16: 46112
A17: Sales | B17: 13260.83 | C17: 16119.77 | D17: 19778.52 | E17: 21052 | F17: 21644 | G17: 28799 | H17: 40575 | I17: 51084 | J17: 60456 | K17: 87584
A18: Raw Material Cost | B18: 9821.14 | C18: 12664.83 | D18: 15170.66 | E18: 16033 | F18: 16292 | G18: 26436 | H18: 32589 | I18: 42103 | J18: 55271 | K18: 80243
A19: Change in Inventory | B19: 313.71 | C19: 978.61 | D19: 776.41 | E19: 878 | F19: -122 | G19: 4795 | H19: 2234 | I19: 2671 | J19: 7815 | K19: 9936
A20: Power and Fuel | B20: 43.84 | C20: 45.32 | D20: 48.51 | E20: 52 | F20: 37 | G20: 45 | H20: 59 | I20: 71 | J20: 78 | K20: 87
A21: Other Mfr. Exp | B21: 160.42 | C21: 124.83 | D21: 193.28 | E21: 215 | F21: 141 | G21: 183 | H21: 225 | I21: 286 | J21: 326 | K21: 375
A22: Employee Cost | B22: 894.32 | C22: 906.26 | D22: 1024.44 | E22: 1204 | F22: 1069 | G22: 1356 | H22: 1656 | I22: 1875 | J22: 2164 | K22: 2692
A23: Selling and admin | B23: 1211.16 | C23: 1277.81 | D23: 1454.32 | E23: 1470 | F23: 1029 | G23: 1697 | H23: 2715 | I23: 3249 | J23: 3494 | K23: 4185
A24: Other Expenses | B24: 279.76 | C24: 435.13 | D24: 669.93 | E24: 493 | F24: 1229 | G24: 533 | H24: 683 | I24: 879 | J24: 1244 | K24: 1581
A25: Other Income | B25: -42.38 | C25: 69.93 | D25: 178.48 | E25: 153 | F25: 180 | G25: 177 | H25: 306 | I25: 534 | J25: 487 | K25: 450
A26: Depreciation | B26: 110.53 | C26: 131.43 | D26: 162.84 | E26: 348 | F26: 375 | G26: 399 | H26: 441 | I26: 584 | J26: 693 | K26: 826
A27: Interest | B27: 37.74 | C27: 52.92 | D27: 52.54 | E27: 166 | F27: 203 | G27: 218 | H27: 300 | I27: 619 | J27: 953 | K27: 1180
... A31: Dividend Amount | B31: 230.83 | C31: 332.92 | D31: 443.9 | E31: 356 | F31: 356 | G31: 667.5 | H31: 890 | I31: 979 | J31: 979 | K31: 1335
A34: Quarters
A35: Report Date | B35: 45382 | C35: 45473 | D35: 45565 | E35: 45657 | F35: 45747 | G35: 45838 | H35: 45930 | I35: 46022 | J35: 46112 | K35: 46203
A36: Sales | B36: 12494 | C36: 13266 | D36: 14534 | E36: 17740 | F36: 14916 | G36: 16523 | H36: 18725 | I36: 25416 | J36: 26920 | K36: 21356
A37: Expenses | B37: 11303 | C37: 12019 | D37: 13298 | E37: 16066 | F37: 13379 | G37: 14693 | H37: 16850 | I37: 22703 | J37: 24982 | K37: 18466
A38: Other Income | B38: 159 | C38: 120 | D38: 123 | E38: 128 | F38: 116 | G38: 105 | H38: 113 | I38: -1 | J38: 235 | K38: 148
A39: Depreciation | B39: 158 | C39: 164 | D39: 171 | E39: 175 | F39: 183 | G39: 184 | H39: 189 | I39: 207 | J39: 246 | K39: 256
A40: Interest | B40: 201 | C40: 230 | D40: 240 | E40: 231 | F40: 252 | G40: 271 | H40: 277 | I40: 282 | J40: 350 | K40: 353
A41: Profit before tax | B41: 991 | C41: 973 | D41: 948 | E41: 1396 | F41: 1218 | G41: 1480 | H41: 1522 | I41: 2223 | J41: 1577 | K41: 2429
A42: Tax | B42: 220 | C42: 258 | D42: 244 | E42: 349 | F42: 347 | G42: 389 | H42: 402 | I42: 539 | J42: 398 | K42: 652
A43: Net profit | B43: 771 | C43: 715 | D43: 704 | E43: 1047 | F43: 871 | G43: 1091 | H43: 1120 | I43: 1684 | J43: 1179 | K43: 1777
A44: Operating Profit | B44: 1191 | C44: 1247 | D44: 1236 | E44: 1674 | F44: 1537 | G44: 1830 | H44: 1875 | I44: 2713 | J44: 1938 | K44: 2890
A47: BALANCE SHEET
A48: Report Date | B48: 42825 | C48: 43190 | D48: 43555 | E48: 43921 | F48: 44286 | G48: 44651 | H48: 45016 | I48: 45382 | J48: 45747 | K48: 46112
A49: Equity Share Capital | B49: 88.78 | C49: 88.78 | D49: 88.78 | E49: 89 | F49: 89 | G49: 89 | H49: 89 | I49: 89 | J49: 89 | K49: 89
A50: Reserves | B50: 4143.6 | C50: 5001.1 | D50: 5981.37 | E50: 6580 | F50: 7408 | G50: 9214 | H50: 11762 | I50: 9304 | J50: 11535 | K50: 15614
A51: Borrowings | B51: 1882.43 | C51: 1691.01 | D51: 2392.98 | E51: 3562 | F51: 5638 | G51: 7275 | H51: 9367 | I51: 15528 | J51: 20777 | K51: 30621
A52: Other Liabilities | B52: 2292.76 | C52: 2740.15 | D52: 3246.71 | E52: 3313 | F52: 3309 | G52: 4610 | H52: 5802 | I52: 6626 | J52: 8244 | K52: 14237
A53: Total | B53: 8407.57 | C53: 9521.04 | D53: 11709.84 | E53: 13544 | F53: 16444 | G53: 21188 | H53: 27020 | I53: 31547 | J53: 40645 | K53: 60561
...

Sheet Data Sheet
A1: metric_name | B1: 42825 | C1: 43190 | D1: 43555 | E1: 43921 | F1: 44286 | G1: 44651 | H1: 45016 | I1: 45382 | J1: 45747 | K1: 46112
A2: Sales | B2: 13260.83 | C2: 16119.77 | D2: 19778.52 | E2: 21052 | F2: 21644 | G2: 28799 | H2: 40575 | I2: 51084 | J2: 60456 | K2: 87584
A3: raw_material_cost | B3: 9821.14 | C3: 12664.83 | D3: 15170.66 | E3: 16033 | F3: 16292 | G3: 26436 | H3: 32589 | I3: 42103 | J3: 55271 | K3: 80243
A4: change_in_inventory | B4: 313.71 | C4: 978.61 | D4: 776.41 | E4: 878 | F4: -122 | G4: 4795 | H4: 2234 | I4: 2671 | J4: 7815 | K4: 9936
A5: power_fuel | B5: 43.84 | C5: 45.32 | D5: 48.51 | E5: 52 | F5: 37 | G5: 45 | H5: 59 | I5: 71 | J5: 78 | K5: 87
A6: other_mfr_exp | B6: 160.42 | C6: 124.83 | D6: 193.28 | E6: 215 | F6: 141 | G6: 183 | H6: 225 | I6: 286 | J6: 326 | K6: 375
A7: employee_cost | B7: 894.32 | C7: 906.26 | D7: 1024.44 | E7: 1204 | F7: 1069 | G7: 1356 | H7: 1656 | I7: 1875 | J7: 2164 | K7: 2692
A8: selling_admin | B8: 1211.16 | C8: 1277.81 | D8: 1454.32 | E8: 1470 | F8: 1029 | G8: 1697 | H8: 2715 | I8: 3249 | J8: 3494 | K8: 4185
A9: other_expenses | B9: 279.76 | C9: 435.13 | D9: 669.93 | E9: 493 | F9: 1229 | G9: 533 | H9: 683 | I9: 879 | J9: 1244 | K9: 1581
A10: other_income | B10: -42.38 | C10: 69.93 | D10: 178.48 | E10: 153 | F10: 180 | G10: 177 | H10: 306 | I10: 534 | J10: 487 | K10: 450
A11: Depreciation | B11: 110.53 | C11: 131.43 | D11: 162.84 | E11: 348 | F11: 375 | G11: 399 | H11: 441 | I11: 584 | J11: 693 | K11: 826
A12: Interest | B12: 37.74 | C12: 52.92 | D12: 52.54 | E12: 166 | F12: 203 | G12: 218 | H12: 300 | I12: 619 | J12: 953 | K12: 1180
... A27: equity_shares | B27: 887786160 | C27: 887786160 | D27: 887786160 | E27: 887786160 | F27: 887786160 | G27: 887786160 | H27: 890000000 | I27: 890000000 | J27: 890000000 | K27: 890000000

Sheet Cash flow Data
B2: 40969 | C2: 41334 | D2: 41699 | E2: 42064 | F2: 42430 | G2: 42795 | H2: 43160 | I2: 43525 | J2: 43891 | K2: 44256 | L2: 44621 | M2: 44986
B3: Cash from Operating Activity - | C3: 18384 | D3: 22163 | E3: 36151 | F3: 35531 | G3: 37900 | H3: 30199 | I3: 23857 | J3: 18891 | K3: 26633 | L3: 29001 | M3: 14283 | N3: 35388
B4: Profit from operations | C4: 22432 | D4: 24406 | E4: 36303 | F4: 43397 | G4: 38626 | H4: 28840 | I4: 33312 | J4: 28771 | K4: 23352 | L4: 31198 | M4: 26943 | N4: 41694
B5: Receivables | C5: -6659 | D5: -5177 | E5: 445 | F5: -3179 | G5: -2223 | H5: -4152 | I5: -10688 | J5: -9109 | K5: 9950 | L5: -5505 | M5: 185 | N5: -2213
B6: Inventory | C6: -2719 | D6: -2656 | E6: -2853 | F6: -3692 | G6: -5743 | H6: -6621 | I6: -3560 | J6: 2069 | K6: 2326 | L6: 3814 | M6: 472 | N6: -5665
B7: Payables | C7: 5867 | D7: 8132 | E7: 4694 | F7: 3598 | G7: 3947 | H7: 9301 | I7: 7320 | J7: -4692 | K7: -8085 | L7: 5748 | M7: -7012 | N7: 6945
B8: Loans Advances | C8: 0 | D8: 0 | E8: 0 | F8: 0 | G8: -520 | H8: 0 | I8: 0 | J8: 0 | K8: 0 | L8: 0 | M8: 0 | N8: 0
B9: Other WC items | C9: 1231 | D9: -303 | E9: 1870 | F9: -398 | G9: 5852 | H9: 4727 | I9: 494 | J9: 4512 | K9: 875 | L9: -4150 | M9: -4396 | N9: -2194
B10: Working capital changes | C10: -2280 | D10: -3 | E10: 4157 | F10: -3672 | G10: 1313 | H10: 3254 | I10: -6434 | J10: -7221 | K10: 5065 | L10: -93 | M10: -10750 | N10: -3127
B11: Direct taxes | C11: -1768 | D11: -2240 | E11: -4308 | F11: -4194 | G11: -2040 | H11: -1895 | I11: -3021 | J11: -2659 | K11: -1785 | L11: -2105 | M11: -1910 | N11: -3179
B12: Cash from Investing Activity - | C12: -19464 | D12: -22969 | E12: -27991 | F12: -36232 | G12: -36694 | H12: -39571 | I12: -25139 | J12: -20878 | K12: -33115 | L12: -25672 | M12: -4444 | N12: -15417
B13: Fixed assets purchased | C13: -13876 | D13: -18863 | E13: -26975 | F13: -31962 | G13: -31503 | H13: -16072 | I13: -35079 | J13: -35304 | K13: -29702 | L13: -20205 | M13: -15168 | N13: -19230
B14: Fixed assets sold | C14: 93 | D14: 37 | E14: 50 | F14: 74 | G14: 59 | H14: 53 | I14: 30 | J14: 67 | K14: 171 | L14: 351 | M14: 230 | N14: 285
... B34: Net Cash Flow | C34: 5488 | D34: -2499 | E34: 4277 | F34: 4500 | G34: -2589 | H34: -3167 | I34: 730 | J34: 6843 | K34: -3092 | L34: 13232 | M34: 6459 | N34: -6272

Sheet Python Output
A1: year | B1: sales | C1: raw_material_cost | D1: change_in_inventory | E1: power_fuel | F1: other_mfr_exp | G1: employee_cost | H1: selling_admin | I1: other_expenses | J1: other_income | K1: depreciation | L1: interest | M1: ebt | N1: tax | O1: net_profit | P1: dividend_amount | Q1: equity_share_cap | R1: total_debt | S1: total_assets | T1: equity_shares | U1: reserves | V1: debt | W1: fixed_assets | X1: debtors | Y1: inventory | Z1: cash_operating | AA1: payables | AB1: cogs | AC1: ebitda | AD1: ebit | AE1: sales_growth | AF1: ebitda_growth | AG1: ebit_growth | AH1: net_profit_growth | AI1: gross_profit | AJ1: gross_margin | AK1: ebitda_margin | AL1: ebit_margin | AM1: ebt_margin | AN1: net_margin | AO1: avg_debtors | AP1: debtor_turnover | AQ1: inventory_turnover | AR1: creditor_turnover | AS1: fixed_asset_turnover | AT1: capital_employed | AU1: capital_turnover | AV1: debtor_days | AW1: payables_days | AX1: inventory_days | AY1: cash_conversion_cycle | AZ1: roce | BA1: interest_coverage | BB1: debt_to_ebitda | BC1: credit
A2: 2017 | B2: 13260.83 | C2: 9821.14 | D2: 313.71 | E2: 43.84 | F2: 160.42 | G2: 894.32 | H2: 1211.16 | I2: 279.76 | J2: -42.38 | K2: 110.53 | L2: 37.74 | M2: 973.25 | N2: 275.97 | O2: 711.47 | P2: 230.83 | Q2: 88.78 | R2: 8407.57 | S2: 8407.57 | T2: 887786160 | U2: 4143.6 | V2: 1882.43 | W2: 1188.72 | X2: 207.6 | Y2: 4925.74 | Z2: 1712.3 | AA2: 2292.76 | AB2: 10606.01 | AC2: 1163.9 | AD2: 1053.37 | AI2: 2654.82 | AJ2: 0.2002 | AK2: 0.0878 | AL2: 0.0794 | AM2: 0.0734 | AN2: 0.0537 | AQ2: 2.69 | AR2: 5.78 | AS2: 11.16 | AT2: 6114.81 | AU2: 2.17 | AW2: 63 | AX2: 136 | AZ2: 0.1723 | BA2: 27.91 | BB2: 1.6 | BC2: Watch
A3: 2018 | B3: 16119.77 | C3: 12664.83 | D3: 978.61 | E3: 45.32 | F3: 124.83 | G3: 906.26 | H3: 1277.81 | I3: 435.13 | J3: 69.93 | K3: 131.43 | L3: 52.92 | M3: 1529.78 | N3: 427.87 | O3: 1130.09 | P3: 332.92 | Q3: 88.78 | R3: 9521.04 | S3: 9521.04 | T3: 887786160 | U3: 5001.1 | V3: 1691.01 | W3: 1473.81 | X3: 295.69 | Y3: 5924.84 | Z3: -51.12 | AA3: 2740.15 | AB3: 12762.63 | AC3: 1644.2 | AD3: 1512.77 | AE3: 0.2156 | AF3: 0.4127 | AG3: 0.4361 | AH3: 0.5884 | AI3: 3357.14 | AJ3: 0.2083 | AK3: 0.102 | AL3: 0.0938 | AM3: 0.0949 | AN3: 0.0701 | AO3: 251.645 | AP3: 64.06 | AQ3: 2.72 | AR3: 5.88 | AS3: 10.94 | AT3: 6780.89 | AU3: 2.38 | AV3: 6 | AW3: 62 | AX3: 134 | AY3: 78 | AZ3: 0.2231 | BA3: 28.59 | BB3: 1 | BC3: Healthy
A4: 2019 | B4: 19778.52 | C4: 15170.66 | D4: 776.41 | E4: 48.51 | F4: 193.28 | G4: 1024.44 | H4: 1454.32 | I4: 669.93 | J4: 178.48 | K4: 162.84 | L4: 52.54 | M4: 1956.89 | N4: 568.24 | O4: 1404.15 | P4: 443.9 | Q4: 88.78 | R4: 11709.84 | S4: 11709.84 | T4: 887786160 | U4: 5981.37 | V4: 2392.98 | W4: 1566.63 | X4: 420.45 | Y4: 7038.82 | Z4: 1242.92 | AA4: 3246.71 | AB4: 15660.48 | AC4: 1993.79 | AD4: 1830.95 | AE4: 0.227 | AF4: 0.2126 | AG4: 0.2103 | AH4: 0.2425 | AI4: 4118.04 | AJ4: 0.2082 | AK4: 0.1008 | AL4: 0.0926 | AM4: 0.0989 | AN4: 0.071 | AO4: 358.07 | AP4: 55.24 | AQ4: 2.81 | AR4: 6.09 | AS4: 12.62 | AT4: 8463.13 | AU4: 2.34 | AV4: 7 | AW4: 60 | AX4: 130 | AY4: 77 | AZ4: 0.2163 | BA4: 34.85 | BB4: 1.2 | BC4: Healthy
A5: 2020 | B5: 21052 | C5: 16033 | D5: 878 | E5: 52 | F5: 215 | G5: 1204 | H5: 1470 | I5: 493 | J5: 153 | K5: 348 | L5: 166 | M5: 2102 | N5: 609 | O5: 1501 | P5: 356 | Q5: 89 | R5: 13544 | S5: 13544 | T5: 887786160 | U5: 6580 | V5: 3562 | W5: 2633 | X5: 312 | Y5: 8103 | Z5: -348 | AA5: 3313 | AB5: 16626 | AC5: 2463 | AD5: 2115 | AE5: 0.0644 | AF5: 0.2353 | AG5: 0.1551 | AH5: 0.069 | AI5: 4426 | AJ5: 0.2102 | AK5: 0.117 | AL5: 0.1005 | AM5: 0.0998 | AN5: 0.0713 | AO5: 366.225 | AP5: 57.48 | AQ5: 2.6 | AR5: 6.35 | AS5: 8 | AT5: 10231 | AU5: 2.06 | AV5: 6 | AW5: 57 | AX5: 140 | AY5: 89 | AZ5: 0.2067 | BA5: 12.74 | BB5: 1.4 | BC5: Healthy
A6: 2021 | B6: 21644 | C6: 16292 | D6: -122 | E6: 37 | F6: 141 | G6: 1069 | H6: 1029 | I6: 1229 | J6: 180 | K6: 375 | L6: 203 | M6: 1327 | N6: 353 | O6: 973 | P6: 356 | Q6: 89 | R6: 16444 | S6: 16444 | T6: 887786160 | U6: 7408 | V6: 5638 | W6: 2523 | X6: 366 | Y6: 8408 | Z6: 4139 | AA6: 3309 | AB6: 17661 | AC6: 1725 | AD6: 1350 | AE6: 0.0281 | AF6: -0.2996 | AG6: -0.3617 | AH6: -0.3518 | AI6: 3983 | AJ6: 0.184 | AK6: 0.0797 | AL6: 0.0624 | AM6: 0.0613 | AN6: 0.045 | AO6: 339 | AP6: 63.85 | AQ6: 2.57 | AR6: 6.54 | AS6: 8.58 | AT6: 13135 | AU6: 1.65 | AV6: 6 | AW6: 56 | AX6: 142 | AY6: 92 | AZ6: 0.1028 | BA6: 6.65 | BB6: 3.3 | BC6: Stress
A7: 2022 | B7: 28799 | C7: 26436 | D7: 4795 | E7: 45 | F7: 183 | G7: 1356 | H7: 1697 | I7: 533 | J7: 177 | K7: 399 | L7: 218 | M7: 2904 | N7: 706 | O7: 2173 | P7: 667.5 | Q7: 89 | R7: 21188 | S7: 21188 | T7: 887786160 | U7: 9214 | V7: 7275 | W7: 2544 | X7: 565 | Y7: 13609 | Z7: -724 | AA7: 4610 | AB7: 23225 | AC7: 3344 | AD7: 2945 | AE7: 0.3306 | AF7: 0.9386 | AG7: 1.1815 | AH7: 1.2333 | AI7: 5574 | AJ7: 0.1935 | AK7: 0.1161 | AL7: 0.1023 | AM7: 0.1008 | AN7: 0.0755 | AO7: 465.5 | AP7: 61.87 | AQ7: 2.12 | AR7: 6.25 | AS7: 11.32 | AT7: 16578 | AU7: 1.74 | AV7: 6 | AW7: 58 | AX7: 172 | AY7: 120 | AZ7: 0.1776 | BA7: 13.51 | BB7: 2.2 | BC7: Watch
A8: 2023 | B8: 40575 | C8: 32589 | D8: 2234 | E8: 59 | F8: 225 | G8: 1656 | H8: 2715 | I8: 683 | J8: 306 | K8: 441 | L8: 300 | M8: 4447 | N8: 1173 | O8: 3250 | P8: 890 | Q8: 89 | R8: 27020 | S8: 27020 | T8: 890000000 | U8: 11762 | V8: 9367 | W8: 2998 | X8: 674 | Y8: 16584 | Z8: 1370 | AA8: 5802 | AB8: 32295 | AC8: 4882 | AD8: 4441 | AE8: 0.4089 | AF8: 0.4599 | AG8: 0.508 | AH8: 0.4956 | AI8: 8280 | AJ8: 0.2041 | AK8: 0.1203 | AL8: 0.1095 | AM8: 0.1096 | AN8: 0.0801 | AO8: 619.5 | AP8: 65.5 | AQ8: 2.45 | AR8: 6.99 | AS8: 13.53 | AT8: 21218 | AU8: 1.91 | AV8: 6 | AW8: 52 | AX8: 149 | AY8: 103 | AZ8: 0.2093 | BA8: 14.8 | BB8: 1.9 | BC8: Watch
A9: 2024 | B9: 51084 | C9: 42103 | D9: 2671 | E9: 71 | F9: 286 | G9: 1875 | H9: 3249 | I9: 879 | J9: 534 | K9: 584 | L9: 619 | M9: 4623 | N9: 1127 | O9: 3496 | P9: 979 | Q9: 89 | R9: 31547 | S9: 31547 | T9: 890000000 | U9: 9304 | V9: 15528 | W9: 3709 | X9: 1018 | Y9: 19051 | Z9: 1695 | AA9: 6626 | AB9: 41664 | AC9: 5292 | AD9: 4708 | AE9: 0.259 | AF9: 0.084 | AG9: 0.0601 | AH9: 0.0757 | AI9: 9420 | AJ9: 0.1844 | AK9: 0.1036 | AL9: 0.0922 | AM9: 0.0905 | AN9: 0.0684 | AO9: 846 | AP9: 60.38 | AQ9: 2.68 | AR9: 7.71 | AS9: 13.77 | AT9: 24921 | AU9: 2.05 | AV9: 6 | AW9: 47 | AX9: 136 | AY9: 95 | AZ9: 0.1889 | BA9: 7.61 | BB9: 2.9 | BC9: Watch
A10: 2025 | B10: 60456 | C10: 55271 | D10: 7815 | E10: 78 | F10: 326 | G10: 2164 | H10: 3494 | I10: 1244 | J10: 487 | K10: 693 | L10: 953 | M10: 4535 | N10: 1198 | O10: 3337 | P10: 979 | Q10: 89 | R10: 40645 | S10: 40645 | T10: 890000000 | U10: 11535 | V10: 20777 | W10: 4062 | X10: 1068 | Y10: 28184 | Z10: -541 | AA10: 8244 | AB10: 50024 | AC10: 5694 | AD10: 5001 | AE10: 0.1835 | AF10: 0.076 | AG10: 0.0622 | AH10: -0.0455 | AI10: 10432 | AJ10: 0.1726 | AK10: 0.0942 | AL10: 0.0827 | AM10: 0.075 | AN10: 0.0552 | AO10: 1043 | AP10: 57.96 | AQ10: 2.15 | AR10: 7.33 | AS10: 14.88 | AT10: 32401 | AU10: 1.87 | AV10: 6 | AW10: 50 | AX10: 170 | AY10: 126 | AZ10: 0.1543 | BA10: 5.25 | BB10: 3.6 | BC10: Stress
A11: 2026 | B11: 87584 | C11: 80243 | D11: 9936 | E11: 87 | F11: 375 | G11: 2692 | H11: 4185 | I11: 1581 | J11: 450 | K11: 826 | L11: 1180 | M11: 6801 | N11: 1728 | O11: 5073 | P11: 1335 | Q11: 89 | R11: 60561 | S11: 60561 | T11: 890000000 | U11: 15614 | V11: 30621 | W11: 6878 | X11: 916 | Y11: 42743 | Z11: 5590 | AA11: 14237 | AB11: 73461 | AC11: 8357 | AD11: 7531 | AE11: 0.4487 | AF11: 0.4677 | AG11: 0.5059 | AH11: 0.5202 | AI11: 14123 | AJ11: 0.1613 | AK11: 0.0954 | AL11: 0.086 | AM11: 0.0777 | AN11: 0.0579 | AO11: 992 | AP11: 88.29 | AQ11: 2.05 | AR11: 6.15 | AS11: 12.73 | AT11: 46324 | AU11: 1.89 | AV11: 4 | AW11: 59 | AX11: 178 | AY11: 123 | AZ11: 0.1626 | BA11: 6.38 | BB11: 3.7 | BC11: Stress

Sheet Python Summary
B1: sales_growth | C1: ebitda_margin | D1: net_margin | E1: debtor_turnover | F1: roce
A2: mean | B2: 0.2406 | C2: 0.1017 | D2: 0.0648 | E2: 63.8478 | F2: 0.1814
A3: median | B3: 0.227 | C3: 0.1014 | D3: 0.0693 | E3: 61.87 | F3: 0.1833

Sheet Sheet1
A1: points to remember
A3: 1 | B3: In Week 4 day 1 - while calculating net income add other incomes also
A9: Questions
A11: if I added the other income value with sales in historical fs , then why I need to do anything in week 4
